[2022-10-31 20:57:47,484] {taskinstance.py:851} INFO - Dependencies all met for <TaskInstance: user_processing.extract_user 2022-10-30T00:00:00+00:00 [queued]>
[2022-10-31 20:57:47,497] {taskinstance.py:851} INFO - Dependencies all met for <TaskInstance: user_processing.extract_user 2022-10-30T00:00:00+00:00 [queued]>
[2022-10-31 20:57:47,497] {taskinstance.py:1042} INFO - 
--------------------------------------------------------------------------------
[2022-10-31 20:57:47,497] {taskinstance.py:1043} INFO - Starting attempt 1 of 1
[2022-10-31 20:57:47,498] {taskinstance.py:1044} INFO - 
--------------------------------------------------------------------------------
[2022-10-31 20:57:47,505] {taskinstance.py:1063} INFO - Executing <Task(SimpleHttpOperator): extract_user> on 2022-10-30T00:00:00+00:00
[2022-10-31 20:57:47,509] {standard_task_runner.py:52} INFO - Started process 97 to run task
[2022-10-31 20:57:47,512] {standard_task_runner.py:76} INFO - Running: ['airflow', 'tasks', 'run', 'user_processing', 'extract_user', '2022-10-30T00:00:00+00:00', '--job-id', '20', '--pool', 'default_pool', '--raw', '--subdir', 'DAGS_FOLDER/user_processing.py', '--cfg-path', '/tmp/tmp_sd7mm8q', '--error-file', '/tmp/tmp4tl5awq6']
[2022-10-31 20:57:47,513] {standard_task_runner.py:77} INFO - Job 20: Subtask extract_user
[2022-10-31 20:57:47,545] {logging_mixin.py:104} INFO - Running <TaskInstance: user_processing.extract_user 2022-10-30T00:00:00+00:00 [running]> on host 8311e947f87b
[2022-10-31 20:57:47,578] {taskinstance.py:1257} INFO - Exporting the following env vars:
AIRFLOW_CTX_DAG_OWNER=airflow
AIRFLOW_CTX_DAG_ID=user_processing
AIRFLOW_CTX_TASK_ID=extract_user
AIRFLOW_CTX_EXECUTION_DATE=2022-10-30T00:00:00+00:00
AIRFLOW_CTX_DAG_RUN_ID=scheduled__2022-10-30T00:00:00+00:00
[2022-10-31 20:57:47,579] {http.py:106} INFO - Calling HTTP method
[2022-10-31 20:57:47,593] {taskinstance.py:1455} ERROR - The conn_id `user_api` isn't defined
Traceback (most recent call last):
  File "/home/airflow/.local/lib/python3.6/site-packages/airflow/models/taskinstance.py", line 1112, in _run_raw_task
    self._prepare_and_execute_task_with_callbacks(context, task)
  File "/home/airflow/.local/lib/python3.6/site-packages/airflow/models/taskinstance.py", line 1285, in _prepare_and_execute_task_with_callbacks
    result = self._execute_task(context, task_copy)
  File "/home/airflow/.local/lib/python3.6/site-packages/airflow/models/taskinstance.py", line 1315, in _execute_task
    result = task_copy.execute(context=context)
  File "/home/airflow/.local/lib/python3.6/site-packages/airflow/providers/http/operators/http.py", line 108, in execute
    response = http.run(self.endpoint, self.data, self.headers, self.extra_options)
  File "/home/airflow/.local/lib/python3.6/site-packages/airflow/providers/http/hooks/http.py", line 122, in run
    session = self.get_conn(headers)
  File "/home/airflow/.local/lib/python3.6/site-packages/airflow/providers/http/hooks/http.py", line 72, in get_conn
    conn = self.get_connection(self.http_conn_id)
  File "/home/airflow/.local/lib/python3.6/site-packages/airflow/hooks/base.py", line 63, in get_connection
    conn = Connection.get_connection_from_secrets(conn_id)
  File "/home/airflow/.local/lib/python3.6/site-packages/airflow/models/connection.py", line 354, in get_connection_from_secrets
    raise AirflowNotFoundException(f"The conn_id `{conn_id}` isn't defined")
airflow.exceptions.AirflowNotFoundException: The conn_id `user_api` isn't defined
[2022-10-31 20:57:47,595] {taskinstance.py:1503} INFO - Marking task as FAILED. dag_id=user_processing, task_id=extract_user, execution_date=20221030T000000, start_date=20221031T205747, end_date=20221031T205747
[2022-10-31 20:57:47,643] {local_task_job.py:146} INFO - Task exited with return code 1
